<?xml version="1.0" ?>
<!-- =================================================================================== -->
<!-- |    This document was autogenerated by xacro from ur_description/urdf/ur10_joint_limited_robot.urdf.xacro | -->
<!-- |    EDITING THIS FILE BY HAND IS NOT RECOMMENDED                                 | -->
<!-- =================================================================================== -->
<robot name="ur10">
  <gazebo>
    <plugin filename="libgazebo_ros_control.so" name="ros_control">
      <!--robotNamespace>/</robotNamespace-->
      <!--robotSimType>gazebo_ros_control/DefaultRobotHWSim</robotSimType-->
    </plugin>
    <!--
    <plugin name="gazebo_ros_power_monitor_controller" filename="libgazebo_ros_power_monitor.so">
      <alwaysOn>true</alwaysOn>
      <updateRate>1.0</updateRate>
      <timeout>5</timeout>
      <powerStateTopic>power_state</powerStateTopic>
      <powerStateRate>10.0</powerStateRate>
      <fullChargeCapacity>87.78</fullChargeCapacity>     
      <dischargeRate>-474</dischargeRate>
      <chargeRate>525</chargeRate>
      <dischargeVoltage>15.52</dischargeVoltage>
      <chargeVoltage>16.41</chargeVoltage>
    </plugin>
-->
  </gazebo>
  <!--
  Author: Kelsey Hawkins
  Contributers: Jimmy Da Silva, Ajit Krisshna N L, Muhammad Asif Rana
-->
  <!-- measured from model -->
  <link name="base_rotated">
    <visual>
      <geometry>
        <mesh filename="package://ecn_manip/robots/ur_description/meshes/ur10/visual/base.dae"/>
      </geometry>
      <material name="LightGrey">
        <color rgba="0.7 0.7 0.7 1.0"/>
      </material>
    </visual>
    <collision>
      <geometry>
        <mesh filename="package://ecn_manip/robots/ur_description/meshes/ur10/collision/base.stl"/>
      </geometry>
    </collision>
    <inertial>
      <mass value="4.0"/>
      <origin rpy="0 0 0" xyz="0.0 0.0 0.0"/>
      <inertia ixx="0.0061063308908" ixy="0.0" ixz="0.0" iyy="0.0061063308908" iyz="0.0" izz="0.01125"/>
    </inertial>
  </link>
  <joint name="shoulder_pan_joint" type="revolute">
    <parent link="base_link"/>
    <child link="shoulder_link"/>
    <origin rpy="0.0 0.0 0.0" xyz="0.0 0.0 0.1273"/>
    <axis xyz="0 0 1"/>
    <limit effort="330.0" lower="-3.141592653589793" upper="3.141592653589793" velocity="2.16"/>
    <dynamics damping="0.0" friction="0.0"/>
  </joint>
  <link name="shoulder_link">
    <visual>
      <geometry>
        <mesh filename="package://ecn_manip/robots/ur_description/meshes/ur10/visual/shoulder.dae"/>
      </geometry>
      <material name="LightGrey">
        <color rgba="0.7 0.7 0.7 1.0"/>
      </material>
    </visual>
    <collision>
      <geometry>
        <mesh filename="package://ecn_manip/robots/ur_description/meshes/ur10/collision/shoulder.stl"/>
      </geometry>
    </collision>
    <inertial>
      <mass value="7.778"/>
      <origin rpy="0 0 0" xyz="0.0 0.0 0.0"/>
      <inertia ixx="0.03147431257693659" ixy="0.0" ixz="0.0" iyy="0.03147431257693659" iyz="0.0" izz="0.021875624999999996"/>
    </inertial>
  </link>
  <joint name="shoulder_lift_joint" type="revolute">
    <parent link="shoulder_link"/>
    <child link="upper_arm_link"/>
    <origin rpy="0.0 1.5707963267948966 0.0" xyz="0.0 0.220941 0.0"/>
    <axis xyz="0 1 0"/>
    <limit effort="330.0" lower="-3.141592653589793" upper="0" velocity="2.16"/>
    <dynamics damping="0.0" friction="0.0"/>
  </joint>
  <link name="upper_arm_link">
    <visual>
      <geometry>
        <mesh filename="package://ecn_manip/robots/ur_description/meshes/ur10/visual/upperarm.dae"/>
      </geometry>
      <material name="LightGrey">
        <color rgba="0.7 0.7 0.7 1.0"/>
      </material>
    </visual>
    <collision>
      <geometry>
        <mesh filename="package://ecn_manip/robots/ur_description/meshes/ur10/collision/upperarm.stl"/>
      </geometry>
    </collision>
    <inertial>
      <mass value="12.93"/>
      <origin rpy="0 0 0" xyz="0.0 0.0 0.306"/>
      <inertia ixx="0.42175380379841093" ixy="0.0" ixz="0.0" iyy="0.42175380379841093" iyz="0.0" izz="0.03636562499999999"/>
    </inertial>
  </link>
  <joint name="elbow_joint" type="revolute">
    <parent link="upper_arm_link"/>
    <child link="forearm_link"/>
    <origin rpy="0.0 0.0 0.0" xyz="0.0 -0.1719 0.612"/>
    <axis xyz="0 1 0"/>
    <limit effort="150.0" lower="-3.141592653589793" upper="3.141592653589793" velocity="3.15"/>
    <dynamics damping="0.0" friction="0.0"/>
  </joint>
  <link name="forearm_link">
    <visual>
      <geometry>
        <mesh filename="package://ecn_manip/robots/ur_description/meshes/ur10/visual/forearm.dae"/>
      </geometry>
      <material name="LightGrey">
        <color rgba="0.7 0.7 0.7 1.0"/>
      </material>
    </visual>
    <collision>
      <geometry>
        <mesh filename="package://ecn_manip/robots/ur_description/meshes/ur10/collision/forearm.stl"/>
      </geometry>
    </collision>
    <inertial>
      <mass value="3.87"/>
      <origin rpy="0 0 0" xyz="0.0 0.0 0.28615"/>
      <inertia ixx="0.11106969409710458" ixy="0.0" ixz="0.0" iyy="0.11106969409710458" iyz="0.0" izz="0.010884375"/>
    </inertial>
  </link>
  <joint name="wrist_1_joint" type="revolute">
    <parent link="forearm_link"/>
    <child link="wrist_1_link"/>
    <origin rpy="0.0 1.5707963267948966 0.0" xyz="0.0 0.0 0.5723"/>
    <axis xyz="0 1 0"/>
    <limit effort="54.0" lower="-3.141592653589793" upper="3.141592653589793" velocity="3.2"/>
    <dynamics damping="0.0" friction="0.0"/>
  </joint>
  <link name="wrist_1_link">
    <visual>
      <geometry>
        <mesh filename="package://ecn_manip/robots/ur_description/meshes/ur10/visual/wrist1.dae"/>
      </geometry>
      <material name="LightGrey">
        <color rgba="0.7 0.7 0.7 1.0"/>
      </material>
    </visual>
    <collision>
      <geometry>
        <mesh filename="package://ecn_manip/robots/ur_description/meshes/ur10/collision/wrist1.stl"/>
      </geometry>
    </collision>
    <inertial>
      <mass value="1.96"/>
      <origin rpy="0 0 0" xyz="0.0 0.0 0.0"/>
      <inertia ixx="0.005108247956699999" ixy="0.0" ixz="0.0" iyy="0.005108247956699999" iyz="0.0" izz="0.005512499999999999"/>
    </inertial>
  </link>
  <joint name="wrist_2_joint" type="revolute">
    <parent link="wrist_1_link"/>
    <child link="wrist_2_link"/>
    <origin rpy="0.0 0.0 0.0" xyz="0.0 0.1149 0.0"/>
    <axis xyz="0 0 1"/>
    <limit effort="54.0" lower="-3.141592653589793" upper="3.141592653589793" velocity="3.2"/>
    <dynamics damping="0.0" friction="0.0"/>
  </joint>
  <link name="wrist_2_link">
    <visual>
      <geometry>
        <mesh filename="package://ecn_manip/robots/ur_description/meshes/ur10/visual/wrist2.dae"/>
      </geometry>
      <material name="LightGrey">
        <color rgba="0.7 0.7 0.7 1.0"/>
      </material>
    </visual>
    <collision>
      <geometry>
        <mesh filename="package://ecn_manip/robots/ur_description/meshes/ur10/collision/wrist2.stl"/>
      </geometry>
    </collision>
    <inertial>
      <mass value="1.96"/>
      <origin rpy="0 0 0" xyz="0.0 0.0 0.0"/>
      <inertia ixx="0.005108247956699999" ixy="0.0" ixz="0.0" iyy="0.005108247956699999" iyz="0.0" izz="0.005512499999999999"/>
    </inertial>
  </link>
  <joint name="wrist_3_joint" type="revolute">
    <parent link="wrist_2_link"/>
    <child link="wrist_3_link"/>
    <origin rpy="0.0 0.0 0.0" xyz="0.0 0.0 0.1157"/>
    <axis xyz="0 1 0"/>
    <limit effort="54.0" lower="-3.141592653589793" upper="3.141592653589793" velocity="3.2"/>
    <dynamics damping="0.0" friction="0.0"/>
  </joint>
  <link name="wrist_3_link">
    <visual>
      <geometry>
        <mesh filename="package://ecn_manip/robots/ur_description/meshes/ur10/visual/wrist3.dae"/>
      </geometry>
      <material name="LightGrey">
        <color rgba="0.7 0.7 0.7 1.0"/>
      </material>
    </visual>
    <collision>
      <geometry>
        <mesh filename="package://ecn_manip/robots/ur_description/meshes/ur10/collision/wrist3.stl"/>
      </geometry>
    </collision>
    <inertial>
      <mass value="0.202"/>
      <origin rpy="0 0 0" xyz="0.0 0.0 0.0"/>
      <inertia ixx="0.000526462289415" ixy="0.0" ixz="0.0" iyy="0.000526462289415" iyz="0.0" izz="0.0005681249999999999"/>
    </inertial>
  </link>
  <joint name="ee_fixed_joint" type="fixed">
    <parent link="wrist_3_link"/>
    <child link="ee_link"/>
    <origin rpy="0.0 0.0 1.5707963267948966" xyz="0.0 0.0922 0.0"/>
  </joint>
  <link name="ee_link">
    <collision>
      <geometry>
        <box size="0.01 0.01 0.01"/>
      </geometry>
      <origin rpy="0 0 0" xyz="-0.01 0 0"/>
    </collision>
  </link>
  <transmission name="shoulder_pan_trans">
    <type>transmission_interface/SimpleTransmission</type>
    <joint name="shoulder_pan_joint">
      <hardwareInterface>hardware_interface/PositionJointInterface</hardwareInterface>
    </joint>
    <actuator name="shoulder_pan_motor">
      <mechanicalReduction>1</mechanicalReduction>
    </actuator>
  </transmission>
  <transmission name="shoulder_lift_trans">
    <type>transmission_interface/SimpleTransmission</type>
    <joint name="shoulder_lift_joint">
      <hardwareInterface>hardware_interface/PositionJointInterface</hardwareInterface>
    </joint>
    <actuator name="shoulder_lift_motor">
      <mechanicalReduction>1</mechanicalReduction>
    </actuator>
  </transmission>
  <transmission name="elbow_trans">
    <type>transmission_interface/SimpleTransmission</type>
    <joint name="elbow_joint">
      <hardwareInterface>hardware_interface/PositionJointInterface</hardwareInterface>
    </joint>
    <actuator name="elbow_motor">
      <mechanicalReduction>1</mechanicalReduction>
    </actuator>
  </transmission>
  <transmission name="wrist_1_trans">
    <type>transmission_interface/SimpleTransmission</type>
    <joint name="wrist_1_joint">
      <hardwareInterface>hardware_interface/PositionJointInterface</hardwareInterface>
    </joint>
    <actuator name="wrist_1_motor">
      <mechanicalReduction>1</mechanicalReduction>
    </actuator>
  </transmission>
  <transmission name="wrist_2_trans">
    <type>transmission_interface/SimpleTransmission</type>
    <joint name="wrist_2_joint">
      <hardwareInterface>hardware_interface/PositionJointInterface</hardwareInterface>
    </joint>
    <actuator name="wrist_2_motor">
      <mechanicalReduction>1</mechanicalReduction>
    </actuator>
  </transmission>
  <transmission name="wrist_3_trans">
    <type>transmission_interface/SimpleTransmission</type>
    <joint name="wrist_3_joint">
      <hardwareInterface>hardware_interface/PositionJointInterface</hardwareInterface>
    </joint>
    <actuator name="wrist_3_motor">
      <mechanicalReduction>1</mechanicalReduction>
    </actuator>
  </transmission>
  <!-- nothing to do here at the moment -->
  <!-- ROS base_link to UR Base Coordinates transform -->
  <link name="base_link"/>
  <joint name="base_rotated-base_fixed_joint" type="fixed">
    <!-- NOTE: this rotation is only needed as long as base_link itself is
                 not corrected wrt the real robot (ie: rotated over 180
                 degrees)
      -->
    <origin rpy="0 0 -3.141592653589793" xyz="0 0 0"/>
    <parent link="base_link"/>
    <child link="base_rotated"/>
  </joint>
  <!-- Frame coincident with all-zeros TCP on UR controller -->
  <link name="tool0">
    <visual>
      <origin xyz="0.0 0.0 -0.05"/>
      <geometry>
        <cylinder length="0.14" radius="0.003"/>
      </geometry>
      <material name="LightGrey">
        <color rgba="0.4 0.4 0.4 1.0"/>
      </material>
    </visual>
  </link>
  <joint name="wrist_3_link-tool0_fixed_joint" type="fixed">
    <origin rpy="-1.5707963267948966 0 0" xyz="0 0.1922 0"/>
    <parent link="wrist_3_link"/>
    <child link="tool0"/>
  </joint>
  <link name="world">
    <visual>
      <geometry>
        <box size="2 2 0.001"/>
      </geometry>
      <material name="LightGrey">
        <color rgba="0.7 0.7 0.7 1.0"/>
      </material>
    </visual>
  </link>
  <joint name="world_joint" type="fixed">
    <parent link="base_link"/>
    <child link="world"/>
    <origin rpy="0.0 0.0 0.0" xyz="0.0 0.0 0.0"/>
  </joint>
</robot>
